Workbook

Sheet vision_cleaned
A1: Effective Date | B1: Fund Name | C1: Option Name | D1: Asset Class Name | E1: Int/Ext | F1: Name/Kind of Investment Item | G1: Currency | H1: Stock ID | I1: Listed Country | J1: Units Held | K1: % Ownership | L1: Address | M1: Value (AUD) | N1: Weighting (%)
A2: 45657 | B2: Vision Super Fund | C2: Balanced growth | D2: Cash | E2: 1 | F2: JP Morgan Chase | G2: AUD | I2: =IF(ISBLANK(H2),"",INDEX(Sheet1!$F$2:$F$936,MATCH(H2,Sheet1!$C$2:$C$936,0))) | M2: -27694956 | N2: -0.0038
A3: 45657 | B3: Vision Super Fund | C3: Balanced growth | D3: Cash | E3: 1 | F3: AUSTRALIA & NEW ZEALAND BANKING GROUP LTD | G3: AUD | I3: =IF(ISBLANK(H3),"",INDEX(Sheet1!$F$2:$F$936,MATCH(H3,Sheet1!$C$2:$C$936,0))) | M3: 4079515.2 | N3: 0.0006
A4: 45657 | B4: Vision Super Fund | C4: Balanced growth | D4: Cash | E4: 1 | F4: CITI GROUP | G4: USD | I4: =IF(ISBLANK(H4),"",INDEX(Sheet1!$F$2:$F$936,MATCH(H4,Sheet1!$C$2:$C$936,0))) | M4: 446108.04 | N4: 0.0001
A5: 45657 | B5: Vision Super Fund | C5: Balanced growth | D5: Cash | E5: 1 | F5: Citibank | G5: AUD | I5: =IF(ISBLANK(H5),"",INDEX(Sheet1!$F$2:$F$936,MATCH(H5,Sheet1!$C$2:$C$936,0))) | M5: 110097.64 | N5: 0
A6: 45657 | B6: Vision Super Fund | C6: Balanced growth | D6: Cash | E6: 1 | F6: COMMONWEALTH BANK OF AUSTRALIA | G6: AUD | I6: =IF(ISBLANK(H6),"",INDEX(Sheet1!$F$2:$F$936,MATCH(H6,Sheet1!$C$2:$C$936,0))) | M6: 76540348 | N6: 0.0106
A7: 45657 | B7: Vision Super Fund | C7: Balanced growth | D7: Cash | E7: 1 | F7: CREDIT AGRICOLE CORP | G7: USD | I7: =IF(ISBLANK(H7),"",INDEX(Sheet1!$F$2:$F$936,MATCH(H7,Sheet1!$C$2:$C$936,0))) | M7: 22078.44 | N7: 0
A8: 45657 | B8: Vision Super Fund | C8: Balanced growth | D8: Cash | E8: 1 | F8: FINISTERRE EMD TRF | G8: AUD | I8: =IF(ISBLANK(H8),"",INDEX(Sheet1!$F$2:$F$936,MATCH(H8,Sheet1!$C$2:$C$936,0))) | M8: 46840410 | N8: 0.0065
A9: 45657 | B9: Vision Super Fund | C9: Balanced growth | D9: Cash | E9: 1 | F9: FINISTERRE EMD TRF | G9: BRL | I9: =IF(ISBLANK(H9),"",INDEX(Sheet1!$F$2:$F$936,MATCH(H9,Sheet1!$C$2:$C$936,0))) | M9: -2025471.7 | N9: -0.0003
A10: 45657 | B10: Vision Super Fund | C10: Balanced growth | D10: Cash | E10: 1 | F10: FINISTERRE EMD TRF | G10: CLP | I10: =IF(ISBLANK(H10),"",INDEX(Sheet1!$F$2:$F$936,MATCH(H10,Sheet1!$C$2:$C$936,0))) | M10: 522578.24 | N10: 0.0001
A11: 45657 | B11: Vision Super Fund | C11: Balanced growth | D11: Cash | E11: 1 | F11: FINISTERRE EMD TRF | G11: CNH | I11: =IF(ISBLANK(H11),"",INDEX(Sheet1!$F$2:$F$936,MATCH(H11,Sheet1!$C$2:$C$936,0))) | M11: -3676120.7 | N11: -0.0005
A12: 45657 | B12: Vision Super Fund | C12: Balanced growth | D12: Cash | E12: 1 | F12: FINISTERRE EMD TRF | G12: CZK | I12: =IF(ISBLANK(H12),"",INDEX(Sheet1!$F$2:$F$936,MATCH(H12,Sheet1!$C$2:$C$936,0))) | M12: -3606.6793 | N12: 0
A13: 45657 | B13: Vision Super Fund | C13: Balanced growth | D13: Cash | E13: 1 | F13: FINISTERRE EMD TRF | G13: EGP | I13: =IF(ISBLANK(H13),"",INDEX(Sheet1!$F$2:$F$936,MATCH(H13,Sheet1!$C$2:$C$936,0))) | M13: 703074.1 | N13: 0.0001
... A67: 45657 | B67: Vision Super Fund | C67: Balanced growth | D67: Cash | E67: 1 | F67: Vision Cash | G67: AUD | I67: =IF(ISBLANK(H67),"",INDEX(Sheet1!$F$2:$F$936,MATCH(H67,Sheet1!$C$2:$C$936,0))) | M67: -2993821.6 | N67: -0.0004
A68: 45657 | B68: Vision Super Fund | C68: Balanced growth | D68: Cash | E68: 1 | F68: Sub Total | I68: =IF(ISBLANK(H68),"",INDEX(Sheet1!$F$2:$F$936,MATCH(H68,Sheet1!$C$2:$C$936,0))) | M68: 3.0353834e+08 | N68: 0.0422
A69: 45657 | B69: Vision Super Fund | C69: Balanced growth | D69: Fixed Income Internal | E69: 0 | F69: AUSTRALIA & NEW ZEALAND BANKING GROUP LTD | I69: =IF(ISBLANK(H69),"",INDEX(Sheet1!$F$2:$F$936,MATCH(H69,Sheet1!$C$2:$C$936,0))) | M69: 11339775 | N69: 0.0016
A70: 45657 | B70: Vision Super Fund | C70: Balanced growth | D70: Fixed Income Internal | E70: 0 | F70: BANK OF QUEENSLAND LTD | I70: =IF(ISBLANK(H70),"",INDEX(Sheet1!$F$2:$F$936,MATCH(H70,Sheet1!$C$2:$C$936,0))) | M70: 41319805 | N70: 0.0057
A71: 45657 | B71: Vision Super Fund | C71: Balanced growth | D71: Fixed Income Internal | E71: 0 | F71: BENDIGO & ADELAIDE BANK LTD | I71: =IF(ISBLANK(H71),"",INDEX(Sheet1!$F$2:$F$936,MATCH(H71,Sheet1!$C$2:$C$936,0))) | M71: 58424440 | N71: 0.0081
A72: 45657 | B72: Vision Super Fund | C72: Balanced growth | D72: Fixed Income Internal | E72: 0 | F72: COMMONWEALTH BANK OF AUSTRALIA | I72: =IF(ISBLANK(H72),"",INDEX(Sheet1!$F$2:$F$936,MATCH(H72,Sheet1!$C$2:$C$936,0))) | M72: 34019584 | N72: 0.0047
A73: 45657 | B73: Vision Super Fund | C73: Balanced growth | D73: Fixed Income Internal | E73: 0 | F73: Norfina Limited | I73: =IF(ISBLANK(H73),"",INDEX(Sheet1!$F$2:$F$936,MATCH(H73,Sheet1!$C$2:$C$936,0))) | M73: 1.2692285e+08 | N73: 0.0176
A74: 45657 | B74: Vision Super Fund | C74: Balanced growth | D74: Fixed Income Internal | E74: 0 | F74: WESTPAC BANKING CORP | I74: =IF(ISBLANK(H74),"",INDEX(Sheet1!$F$2:$F$936,MATCH(H74,Sheet1!$C$2:$C$936,0))) | M74: 70747519 | N74: 0.0098
A75: 45657 | B75: Vision Super Fund | C75: Balanced growth | D75: Fixed Income Internal | E75: 0 | F75: Sub Total | I75: =IF(ISBLANK(H75),"",INDEX(Sheet1!$F$2:$F$936,MATCH(H75,Sheet1!$C$2:$C$936,0))) | M75: 3.4277397e+08 | N75: 0.0475
A76: 45657 | B76: Vision Super Fund | C76: Balanced growth | D76: Fixed Income External | E76: 1 | F76: Amundi Singapore Limited | I76: =IF(ISBLANK(H76),"",INDEX(Sheet1!$F$2:$F$936,MATCH(H76,Sheet1!$C$2:$C$936,0))) | M76: 8.7235174e+08 | N76: 0.1208
A77: 45657 | B77: Vision Super Fund | C77: Balanced growth | D77: Fixed Income External | E77: 1 | F77: Barings Global Advisers Limited | I77: =IF(ISBLANK(H77),"",INDEX(Sheet1!$F$2:$F$936,MATCH(H77,Sheet1!$C$2:$C$936,0))) | M77: 70867353 | N77: 0.0098
A78: 45657 | B78: Vision Super Fund | C78: Balanced growth | D78: Fixed Income External | E78: 1 | F78: Brandywine Global Investment Management, LLC | I78: =IF(ISBLANK(H78),"",INDEX(Sheet1!$F$2:$F$936,MATCH(H78,Sheet1!$C$2:$C$936,0))) | M78: 1.1700671e+08 | N78: 0.0162
A79: 45657 | B79: Vision Super Fund | C79: Balanced growth | D79: Fixed Income External | E79: 1 | F79: IFM Investors Pty Ltd | I79: =IF(ISBLANK(H79),"",INDEX(Sheet1!$F$2:$F$936,MATCH(H79,Sheet1!$C$2:$C$936,0))) | M79: 2.1002435e+08 | N79: 0.0291
... A82: 45657 | B82: Vision Super Fund | C82: Balanced growth | D82: Fixed Income External | E82: 1 | F82: Sub Total | I82: =IF(ISBLANK(H82),"",INDEX(Sheet1!$F$2:$F$936,MATCH(H82,Sheet1!$C$2:$C$936,0))) | M82: 1.4128488e+09 | N82: 0.1957
A83: 45657 | B83: Vision Super Fund | C83: Balanced growth | D83: Listed Equity | E83: 1 | F83: 29METALS LTD COMMON STOCK AUD | H83: BNNVRL0 | I83: =IF(ISBLANK(H83),"",INDEX(Sheet1!$F$2:$F$936,MATCH(H83,Sheet1!$C$2:$C$936,0))) -> Australia | J83: 2329363 | M83: 570693.85 | N83: 0.0001
A84: 45657 | B84: Vision Super Fund | C84: Balanced growth | D84: Listed Equity | E84: 1 | F84: 3I GROUP PLC COMMON STOCK GBP 73.8636 | H84: B1YW440 | I84: =IF(ISBLANK(H84),"",INDEX(Sheet1!$F$2:$F$936,MATCH(H84,Sheet1!$C$2:$C$936,0))) -> United Kingdom | J84: 34243 | M84: 2468616.6 | N84: 0.0003
A85: 45657 | B85: Vision Super Fund | C85: Balanced growth | D85: Listed Equity | E85: 1 | F85: A2 MILK CO LTD/THE COMMON STOCK NZD 0 | H85: 2F5232S | I85: =IF(ISBLANK(H85),"",INDEX(Sheet1!$F$2:$F$936,MATCH(H85,Sheet1!$C$2:$C$936,0))) -> NZD | J85: 287841 | M85: 1660843.3 | N85: 0.0002
A86: 45657 | B86: Vision Super Fund | C86: Balanced growth | D86: Listed Equity | E86: 1 | F86: ABB INDIA LTD COMMON STOCK INR 2 | H86: B1Y9QS9 | I86: =IF(ISBLANK(H86),"",INDEX(Sheet1!$F$2:$F$936,MATCH(H86,Sheet1!$C$2:$C$936,0))) -> INR | J86: 6043 | M86: 786440.09 | N86: 0.0001
A87: 45657 | B87: Vision Super Fund | C87: Balanced growth | D87: Listed Equity | E87: 1 | F87: ABB LTD COMMON STOCK CHF 0.12 | H87: 7108899 | I87: =IF(ISBLANK(H87),"",INDEX(Sheet1!$F$2:$F$936,MATCH(H87,Sheet1!$C$2:$C$936,0))) -> Switzerland | J87: 44228 | M87: 3867102.4 | N87: 0.0005
A88: 45657 | B88: Vision Super Fund | C88: Balanced growth | D88: Listed Equity | E88: 1 | F88: ABBOTT LABORATORIES COMMON STOCK USD 0 | H88: 2002305 | I88: =IF(ISBLANK(H88),"",INDEX(Sheet1!$F$2:$F$936,MATCH(H88,Sheet1!$C$2:$C$936,0))) -> United States | J88: 39262 | M88: 7174547.3 | N88: 0.001
A89: 45657 | B89: Vision Super Fund | C89: Balanced growth | D89: Listed Equity | E89: 1 | F89: ABBVIE INC COMMON STOCK USD 0.01 | H89: B92SR70 | I89: =IF(ISBLANK(H89),"",INDEX(Sheet1!$F$2:$F$936,MATCH(H89,Sheet1!$C$2:$C$936,0))) -> United States | J89: 35141 | M89: 10090817 | N89: 0.0014
A90: 45657 | B90: Vision Super Fund | C90: Balanced growth | D90: Listed Equity | E90: 1 | F90: ACCENT GROUP LTD COMMON STOCK AUD 0 | H90: BD20RS5 | I90: =IF(ISBLANK(H90),"",INDEX(Sheet1!$F$2:$F$936,MATCH(H90,Sheet1!$C$2:$C$936,0))) -> AUD | J90: 807271 | M90: 1889015.3 | N90: 0.0003
A91: 45657 | B91: Vision Super Fund | C91: Balanced growth | D91: Listed Equity | E91: 1 | F91: ACCENTURE PLC COMMON STOCK USD 0.0000225 | H91: B4BNMY3 | I91: =IF(ISBLANK(H91),"",INDEX(Sheet1!$F$2:$F$936,MATCH(H91,Sheet1!$C$2:$C$936,0))) -> United States | J91: 3300 | M91: 1876816.5 | N91: 0.0003
A92: 45657 | B92: Vision Super Fund | C92: Balanced growth | D92: Listed Equity | E92: 1 | F92: ACS ACTIVIDADES DE CONSTRUCCION Y SERVICIOS SA | H92: B01FLQ6 | I92: =IF(ISBLANK(H92),"",INDEX(Sheet1!$F$2:$F$936,MATCH(H92,Sheet1!$C$2:$C$936,0))) -> Spain | J92: 41234 | M92: 3340498.4 | N92: 0.0005
A93: 45657 | B93: Vision Super Fund | C93: Balanced growth | D93: Listed Equity | E93: 1 | F93: ADAIRS LTD COMMON STOCK AUD | H93: BYYT7Q5 | I93: =IF(ISBLANK(H93),"",INDEX(Sheet1!$F$2:$F$936,MATCH(H93,Sheet1!$C$2:$C$936,0))) -> AUD | J93: 435634 | M93: 1176211.7 | N93: 0.0002
A94: 45657 | B94: Vision Super Fund | C94: Balanced growth | D94: Listed Equity | E94: 1 | F94: ADOBE INC COMMON STOCK USD 0.0001 | H94: 2008154 | I94: =IF(ISBLANK(H94),"",INDEX(Sheet1!$F$2:$F$936,MATCH(H94,Sheet1!$C$2:$C$936,0))) -> United States | J94: 7598 | M94: 5456460.1 | N94: 0.0008
A95: 45657 | B95: Vision Super Fund | C95: Balanced growth | D95: Listed Equity | E95: 1 | F95: ADVANCED MICRO DEVICES INC COMMON STOCK USD 0.01 | H95: 2007849 | I95: =IF(ISBLANK(H95),"",INDEX(Sheet1!$F$2:$F$936,MATCH(H95,Sheet1!$C$2:$C$936,0))) -> United States | J95: 29622 | M95: 5778436.1 | N95: 0.0008
...

Sheet Sheet1
B1: Name | C1: Stock Id | D1: cross check with Ausie Super | E1: Manual | F1: Combine
B2: 29METALS LTD COMMON STOCK AUD | C2: BNNVRL0 | D2: Australia | F2: =_xlfn.IFNA(D2,E2) -> Australia | I2: {=SUM(INT(ISNA(D2:D936)))} -> 326 | J2: =I2/COUNTA(C2:C936) -> 0.3486631
B3: 3I GROUP PLC COMMON STOCK GBP 73.8636 | C3: B1YW440 | D3: United Kingdom | F3: =_xlfn.IFNA(D3,E3) -> United Kingdom
B4: A2 MILK CO LTD/THE COMMON STOCK NZD 0 | C4: 2F5232S | D4: #N/A | E4: NZD | F4: =_xlfn.IFNA(D4,E4) -> NZD
B5: ABB INDIA LTD COMMON STOCK INR 2 | C5: B1Y9QS9 | D5: #N/A | E5: INR | F5: =_xlfn.IFNA(D5,E5) -> INR
B6: ABB LTD COMMON STOCK CHF 0.12 | C6: 7108899 | D6: Switzerland | F6: =_xlfn.IFNA(D6,E6) -> Switzerland
B7: ABBOTT LABORATORIES COMMON STOCK USD 0 | C7: 2002305 | D7: United States | F7: =_xlfn.IFNA(D7,E7) -> United States
B8: ABBVIE INC COMMON STOCK USD 0.01 | C8: B92SR70 | D8: United States | F8: =_xlfn.IFNA(D8,E8) -> United States
B9: ACCENT GROUP LTD COMMON STOCK AUD 0 | C9: BD20RS5 | D9: #N/A | E9: AUD | F9: =_xlfn.IFNA(D9,E9) -> AUD
B10: ACCENTURE PLC COMMON STOCK USD 0.0000225 | C10: B4BNMY3 | D10: United States | F10: =_xlfn.IFNA(D10,E10) -> United States
B11: ACS ACTIVIDADES DE CONSTRUCCION Y SERVICIOS SA | C11: B01FLQ6 | D11: Spain | F11: =_xlfn.IFNA(D11,E11) -> Spain
B12: ADAIRS LTD COMMON STOCK AUD | C12: BYYT7Q5 | D12: #N/A | E12: AUD | F12: =_xlfn.IFNA(D12,E12) -> AUD
B13: ADOBE INC COMMON STOCK USD 0.0001 | C13: 2008154 | D13: United States | F13: =_xlfn.IFNA(D13,E13) -> United States
B14: ADVANCED MICRO DEVICES INC COMMON STOCK USD 0.01 | C14: 2007849 | D14: United States | F14: =_xlfn.IFNA(D14,E14) -> United States
B15: ADVANTEST CORP COMMON STOCK JPY | C15: 6870490 | D15: Japan | F15: =_xlfn.IFNA(D15,E15) -> Japan
B16: ADYEN NV COMMON STOCK EUR 0.01 | C16: BZ1HM42 | D16: Netherlands | F16: =_xlfn.IFNA(D16,E16) -> Netherlands
B17: AERCAP HOLDINGS NV COMMON STOCK USD 0.01 | C17: B1HHKD3 | D17: Ireland | F17: =_xlfn.IFNA(D17,E17) -> Ireland
B18: AFLAC INC COMMON STOCK USD 0.1 | C18: 2026361 | D18: United States | F18: =_xlfn.IFNA(D18,E18) -> United States
B19: AGEAS SA/NV COMMON STOCK EUR 0 | C19: B86S2N0 | D19: Belgium | F19: =_xlfn.IFNA(D19,E19) -> Belgium
B20: AGILENT TECHNOLOGIES INC COMMON STOCK USD 0.01 | C20: 2520153 | D20: United States | F20: =_xlfn.IFNA(D20,E20) -> United States
B21: AGNICO EAGLE MINES LTD COMMON STOCK CAD 0 | C21: 2009823 | D21: Canada | F21: =_xlfn.IFNA(D21,E21) -> Canada
B22: AIA GROUP LTD COMMON STOCK HKD 0 | C22: B4TX8S1 | D22: Hong Kong | F22: =_xlfn.IFNA(D22,E22) -> Hong Kong
B23: AIB GROUP PLC COMMON STOCK EUR 0.625 | C23: BF0L353 | D23: Ireland | F23: =_xlfn.IFNA(D23,E23) -> Ireland
B24: AIR CANADA COMMON STOCK CAD 0 | C24: BSDHYK1 | D24: Canada | F24: =_xlfn.IFNA(D24,E24) -> Canada
B25: AIRBUS SE COMMON STOCK EUR 1 | C25: 4012250 | D25: Netherlands | F25: =_xlfn.IFNA(D25,E25) -> Netherlands
B26: AKBANK TAS COMMON STOCK TRY 1 | C26: B03MN70 | D26: #N/A | E26: TRY | F26: =_xlfn.IFNA(D26,E26) -> TRY
B27: AL RAJHI BANK COMMON STOCK SAR 10 | C27: B12LZH9 | D27: #N/A | E27: SAR | F27: =_xlfn.IFNA(D27,E27) -> SAR
B28: ALDAR PROPERTIES PJSC COMMON STOCK AED 1 | C28: B0LX3Y2 | D28: UAE | F28: =_xlfn.IFNA(D28,E28) -> UAE
B29: ALIBABA GROUP HOLDING LTD ADR USD 0.000025 | C29: BP41ZD1 | D29: China | F29: =_xlfn.IFNA(D29,E29) -> China
B30: ALIBABA GROUP HOLDING LTD COMMON STOCK HKD | C30: BK6YZP5 | D30: China | F30: =_xlfn.IFNA(D30,E30) -> China
B31: ALLEGION PLC COMMON STOCK USD 0.01 | C31: BFRT3W7 | D31: #N/A | E31: USD | F31: =_xlfn.IFNA(D31,E31) -> USD
B32: ALLIANZ SE COMMON STOCK EUR 0 | C32: 5231485 | D32: Germany | F32: =_xlfn.IFNA(D32,E32) -> Germany
B33: ALPHABET INC COMMON STOCK USD 0.001 | C33: BYVY8G0 | D33: United States | F33: =_xlfn.IFNA(D33,E33) -> United States
B34: ALPHABET INC COMMON STOCK USD 0.001 | C34: BYY88Y7 | D34: United States | F34: =_xlfn.IFNA(D34,E34) -> United States
B35: ALS LTD COMMON STOCK AUD 0 | C35: B86SZR5 | D35: Australia | F35: =_xlfn.IFNA(D35,E35) -> Australia
B36: AMADEUS IT GROUP SA COMMON STOCK EUR 0.01 | C36: B3MSM28 | D36: Spain | F36: =_xlfn.IFNA(D36,E36) -> Spain
B37: AMAZON.COM INC COMMON STOCK USD 0.01 | C37: 2000019 | D37: United States | F37: =_xlfn.IFNA(D37,E37) -> United States
B38: AMCOR PLC CDI AUD 0 | C38: 3F0936S | D38: #N/A | E38: AUD | F38: =_xlfn.IFNA(D38,E38) -> AUD
B39: AMCOR PLC COMMON STOCK USD 0.01 | C39: BJ1F307 | D39: United Kingdom | F39: =_xlfn.IFNA(D39,E39) -> United Kingdom
B40: AMERICAN EXPRESS CO COMMON STOCK USD 0.2 | C40: 2026082 | D40: United States | F40: =_xlfn.IFNA(D40,E40) -> United States
...
